Workbook
Name Slicer_Weight_Status: #N/A

Sheet Customer Names
A1: Customer ID | B1: name
A2: Id1 | B2: Hawks, Ms. Kelly
A3: Id2 | B3: Lehner, Mr. Matthew D
A4: Id3 | B4: Lu, Mr. Phil
A5: Id4 | B5: Osborne, Ms. Kelsey
A6: Id5 | B6: Kadala, Ms. Kristyn
A7: Id6 | B7: Baker, Mr. Russell B.
A8: Id7 | B8: Macpherson, Mr. Scott
A9: Id8 | B9: Hallman, Mr. Stephen
A10: Id9 | B10: Moran, Mr. Patrick R.
A11: Id10 | B11: Benner, Ms. Brooke N.
A12: Id11 | B12: Fierro Vargas, Ms. Paola Andrea
... A2336: Id2335 | B2336: German, Mr. Aaron K

Sheet Medical Examinations
A1: Customer ID | B1: BMI | C1: HBA1C | D1: Heart Issues | E1: Any Transplants | F1: Cancer history | G1: NumberOfMajorSurgeries | H1: smoker
A2: Id1 | B2: 47.41 | C2: 7.47 | D2: No | E2: No | F2: No | G2: No major surgery | H2: yes
A3: Id2 | B3: 30.36 | C3: 5.77 | D3: No | E3: No | F3: No | G3: No major surgery | H3: yes
A4: Id3 | B4: 34.485 | C4: 11.87 | D4: yes | E4: No | F4: No | G4: 2 | H4: yes
A5: Id4 | B5: 38.095 | C5: 6.05 | D5: No | E5: No | F5: No | G5: No major surgery | H5: yes
A6: Id5 | B6: 35.53 | C6: 5.45 | D6: No | E6: No | F6: No | G6: No major surgery | H6: yes
A7: Id6 | B7: 32.8 | C7: 6.59 | D7: No | E7: No | F7: No | G7: No major surgery | H7: yes
A8: Id7 | B8: 36.4 | C8: 6.07 | D8: No | E8: No | F8: No | G8: No major surgery | H8: yes
A9: Id8 | B9: 36.96 | C9: 7.93 | D9: No | E9: No | F9: No | G9: 3 | H9: yes
A10: Id9 | B10: 41.14 | C10: 9.58 | D10: yes | E10: No | F10: Yes | G10: 1 | H10: yes
A11: Id10 | B11: 38.06 | C11: 10.79 | D11: No | E11: No | F11: No | G11: No major surgery | H11: yes
A12: Id11 | B12: 37.7 | C12: 5.96 | D12: yes | E12: No | F12: No | G12: 2 | H12: yes
A13: Id12 | B13: 42.13 | C13: 11.9 | D13: No | E13: No | F13: No | G13: No major surgery | H13: yes
A14: Id13 | B14: 40.92 | C14: 8.41 | D14: No | E14: No | F14: No | G14: No major surgery | H14: yes
A15: Id14 | B15: 40.565 | C15: 7.02 | D15: No | E15: No | F15: No | G15: No major surgery | H15: yes
A16: Id15 | B16: 36.385 | C16: 7.59 | D16: yes | E16: No | F16: No | G16: 2 | H16: yes
A17: Id16 | B17: 39.9 | C17: 11.32 | D17: No | E17: No | F17: No | G17: No major surgery | H17: yes
A18: Id17 | B18: 33.8 | C18: 7.67 | D18: No | E18: No | F18: No | G18: 3 | H18: yes
A19: Id18 | B19: 36.765 | C19: 7.29 | D19: yes | E19: No | F19: Yes | G19: 1 | H19: yes
A20: Id19 | B20: 36.955 | C20: 4.72 | D20: yes | E20: No | F20: No | G20: 1 | H20: yes
A21: Id20 | B21: 42.9 | C21: 11.41 | D21: No | E21: No | F21: No | G21: No major surgery | H21: yes
A22: Id21 | B22: 36.3 | C22: 11.5 | D22: yes | E22: No | F22: No | G22: 2 | H22: yes
A23: Id22 | B23: 32.2 | C23: 6.22 | D23: yes | E23: No | F23: No | G23: 2 | H23: yes
A24: Id23 | B24: 31.3 | C24: 11.38 | D24: No | E24: No | F24: No | G24: 3 | H24: yes
A25: Id24 | B25: 41.8 | C25: 7.89 | D25: yes | E25: No | F25: No | G25: 2 | H25: yes
A26: Id25 | B26: 35.09 | C26: 4.38 | D26: yes | E26: No | F26: No | G26: 2 | H26: yes
A27: Id26 | B27: 33.88 | C27: 7.01 | D27: No | E27: No | F27: No | G27: 3 | H27: yes
A28: Id27 | B28: 30.875 | C28: 11.88 | D28: No | E28: No | F28: No | G28: No major surgery | H28: yes
A29: Id28 | B29: 36.86 | C29: 5.19 | D29: yes | E29: No | F29: Yes | G29: 1 | H29: yes
A30: Id29 | B30: 35.86 | C30: 6.74 | D30: yes | E30: No | F30: No | G30: 2 | H30: yes
A31: Id30 | B31: 37.05 | C31: 8.44 | D31: No | E31: No | F31: No | G31: No major surgery | H31: yes
A32: Id31 | B32: 43.89 | C32: 8.71 | D32: No | E32: No | F32: No | G32: No major surgery | H32: yes
A33: Id32 | B33: 42.35 | C33: 5.08 | D33: yes | E33: No | F33: No | G33: No major surgery | H33: yes
A34: Id33 | B34: 31.35 | C34: 6.86 | D34: No | E34: No | F34: No | G34: No major surgery | H34: yes
A35: Id34 | B35: 47.6 | C35: 5.95 | D35: yes | E35: No | F35: No | G35: No major surgery | H35: yes
A36: Id35 | B36: 46.2 | C36: 6.09 | D36: No | E36: No | F36: Yes | G36: 1 | H36: yes
A37: Id36 | B37: 32.015 | C37: 11.75 | D37: No | E37: No | F37: No | G37: No major surgery | H37: yes
A38: Id37 | B38: 40.565 | C38: 7.37 | D38: No | E38: No | F38: No | G38: No major surgery | H38: yes
A39: Id38 | B39: 32.45 | C39: 11.91 | D39: No | E39: No | F39: No | G39: No major surgery | H39: yes
A40: Id39 | B40: 34.96 | C40: 6.52 | D40: No | E40: No | F40: No | G40: No major surgery | H40: yes
...

Sheet PWQ_Medical Examinations (2)
A1: Customer ID | B1: BMI | C1: Weight Status | D1: HBA1C | E1: Heart Issues | F1: Any Transplants | G1: Cancer history | H1: NumberOfMajorSurgeries | I1: smoker | J1: Diabetic Status
A2: Id1 | B2: 47.41 | C2: Obesity | D2: 7.47 | E2: No | F2: No | G2: No | H2: 0 | I2: yes | J2: =IF(Medical_Examinations[[#This Row],[HBA1C]]<5.7,"Normal",IF(Medical_Examinations[[#This Row],[HBA1C]]<=6.4,"Prediabetes",IF(Medical_Examinations[[#This Row],[HBA1C]]>=6.4,"Diabetes"))) -> Diabetes
A3: Id2 | B3: 30.36 | C3: Obesity | D3: 5.77 | E3: No | F3: No | G3: No | H3: 0 | I3: yes | J3: =IF(Medical_Examinations[[#This Row],[HBA1C]]<5.7,"Normal",IF(Medical_Examinations[[#This Row],[HBA1C]]<=6.4,"Prediabetes",IF(Medical_Examinations[[#This Row],[HBA1C]]>=6.4,"Diabetes"))) -> Prediabetes
A4: Id3 | B4: 34.485 | C4: Obesity | D4: 11.87 | E4: yes | F4: No | G4: No | H4: 2 | I4: yes | J4: =IF(Medical_Examinations[[#This Row],[HBA1C]]<5.7,"Normal",IF(Medical_Examinations[[#This Row],[HBA1C]]<=6.4,"Prediabetes",IF(Medical_Examinations[[#This Row],[HBA1C]]>=6.4,"Diabetes"))) -> Diabetes
A5: Id4 | B5: 38.095 | C5: Obesity | D5: 6.05 | E5: No | F5: No | G5: No | H5: 0 | I5: yes | J5: =IF(Medical_Examinations[[#This Row],[HBA1C]]<5.7,"Normal",IF(Medical_Examinations[[#This Row],[HBA1C]]<=6.4,"Prediabetes",IF(Medical_Examinations[[#This Row],[HBA1C]]>=6.4,"Diabetes"))) -> Prediabetes
A6: Id5 | B6: 35.53 | C6: Obesity | D6: 5.45 | E6: No | F6: No | G6: No | H6: 0 | I6: yes | J6: =IF(Medical_Examinations[[#This Row],[HBA1C]]<5.7,"Normal",IF(Medical_Examinations[[#This Row],[HBA1C]]<=6.4,"Prediabetes",IF(Medical_Examinations[[#This Row],[HBA1C]]>=6.4,"Diabetes"))) -> Normal
A7: Id6 | B7: 32.8 | C7: Obesity | D7: 6.59 | E7: No | F7: No | G7: No | H7: 0 | I7: yes | J7: =IF(Medical_Examinations[[#This Row],[HBA1C]]<5.7,"Normal",IF(Medical_Examinations[[#This Row],[HBA1C]]<=6.4,"Prediabetes",IF(Medical_Examinations[[#This Row],[HBA1C]]>=6.4,"Diabetes"))) -> Diabetes
A8: Id7 | B8: 36.4 | C8: Obesity | D8: 6.07 | E8: No | F8: No | G8: No | H8: 0 | I8: yes | J8: =IF(Medical_Examinations[[#This Row],[HBA1C]]<5.7,"Normal",IF(Medical_Examinations[[#This Row],[HBA1C]]<=6.4,"Prediabetes",IF(Medical_Examinations[[#This Row],[HBA1C]]>=6.4,"Diabetes"))) -> Prediabetes
A9: Id8 | B9: 36.96 | C9: Obesity | D9: 7.93 | E9: No | F9: No | G9: No | H9: 3 | I9: yes | J9: =IF(Medical_Examinations[[#This Row],[HBA1C]]<5.7,"Normal",IF(Medical_Examinations[[#This Row],[HBA1C]]<=6.4,"Prediabetes",IF(Medical_Examinations[[#This Row],[HBA1C]]>=6.4,"Diabetes"))) -> Diabetes
A10: Id9 | B10: 41.14 | C10: Obesity | D10: 9.58 | E10: yes | F10: No | G10: Yes | H10: 1 | I10: yes | J10: =IF(Medical_Examinations[[#This Row],[HBA1C]]<5.7,"Normal",IF(Medical_Examinations[[#This Row],[HBA1C]]<=6.4,"Prediabetes",IF(Medical_Examinations[[#This Row],[HBA1C]]>=6.4,"Diabetes"))) -> Diabetes
A11: Id10 | B11: 38.06 | C11: Obesity | D11: 10.79 | E11: No | F11: No | G11: No | H11: 0 | I11: yes | J11: =IF(Medical_Examinations[[#This Row],[HBA1C]]<5.7,"Normal",IF(Medical_Examinations[[#This Row],[HBA1C]]<=6.4,"Prediabetes",IF(Medical_Examinations[[#This Row],[HBA1C]]>=6.4,"Diabetes"))) -> Diabetes
A12: Id11 | B12: 37.7 | C12: Obesity | D12: 5.96 | E12: yes | F12: No | G12: No | H12: 2 | I12: yes | J12: =IF(Medical_Examinations[[#This Row],[HBA1C]]<5.7,"Normal",IF(Medical_Examinations[[#This Row],[HBA1C]]<=6.4,"Prediabetes",IF(Medical_Examinations[[#This Row],[HBA1C]]>=6.4,"Diabetes"))) -> Prediabetes
A13: Id12 | B13: 42.13 | C13: Obesity | D13: 11.9 | E13: No | F13: No | G13: No | H13: 0 | I13: yes | J13: =IF(Medical_Examinations[[#This Row],[HBA1C]]<5.7,"Normal",IF(Medical_Examinations[[#This Row],[HBA1C]]<=6.4,"Prediabetes",IF(Medical_Examinations[[#This Row],[HBA1C]]>=6.4,"Diabetes"))) -> Diabetes
... A2336: Id2335 | B2336: 17.58 | C2336: Under Weight | D2336: 4.51 | E2336: No | F2336: No | G2336: No | H2336: 1 | I2336: No | J2336: =IF(Medical_Examinations[[#This Row],[HBA1C]]<5.7,"Normal",IF(Medical_Examinations[[#This Row],[HBA1C]]<=6.4,"Prediabetes",IF(Medical_Examinations[[#This Row],[HBA1C]]>=6.4,"Diabetes"))) -> Normal

Sheet PWQ_Customer Names (2)
A1: Customer ID | B1: last Name | C1: Title | D1: First Name
A2: Id1 | B2: Hawks | C2: Ms | D2: Kelly
A3: Id2 | B3: Lehner | C3: Mr | D3: Matthew D
A4: Id3 | B4: Lu | C4: Mr | D4: Phil
A5: Id4 | B5: Osborne | C5: Ms | D5: Kelsey
A6: Id5 | B6: Kadala | C6: Ms | D6: Kristyn
A7: Id6 | B7: Baker | C7: Mr | D7: Russell B
A8: Id7 | B8: Macpherson | C8: Mr | D8: Scott
A9: Id8 | B9: Hallman | C9: Mr | D9: Stephen
A10: Id9 | B10: Moran | C10: Mr | D10: Patrick R
A11: Id10 | B11: Benner | C11: Ms | D11: Brooke N
A12: Id11 | B12: Fierro Vargas | C12: Ms | D12: Paola Andrea
... A2336: Id2335 | B2336: German | C2336: Mr | D2336: Aaron K

Sheet PWQ_Hospitalisation Details (2)
A1: Customer ID | B1: year | C1: month | D1: date | E1: Date of Birth | F1: children | G1: charges | H1: Hospital tier | I1: City tier | J1: State ID | K1: Age
A2: Id2335 | B2: 1992 | C2: Jul | D2: 9 | E2: 33794 | F2: 0 | G2: 563.84 | H2: tier - 2 | I2: tier - 3 | J2: R1013 | K2: =DATEDIF(Hospitalisation_Details[[#This Row],[Date of Birth]],$L$2,"Y") -> 30 | L2: 45085
A3: Id2334 | B3: 1992 | C3: Nov | D3: 30 | E3: 33938 | F3: 0 | G3: 570.62 | H3: tier - 2 | I3: tier - 1 | J3: R1013 | K3: =DATEDIF(Hospitalisation_Details[[#This Row],[Date of Birth]],$L$2,"Y") -> 30
A4: Id2333 | B4: 1993 | C4: Jun | D4: 30 | E4: 34150 | F4: 0 | G4: 600 | H4: tier - 2 | I4: tier - 1 | J4: R1013 | K4: =DATEDIF(Hospitalisation_Details[[#This Row],[Date of Birth]],$L$2,"Y") -> 29
A5: Id2332 | B5: 1992 | C5: Sep | D5: 13 | E5: 33860 | F5: 0 | G5: 604.54 | H5: tier - 3 | I5: tier - 3 | J5: R1013 | K5: =DATEDIF(Hospitalisation_Details[[#This Row],[Date of Birth]],$L$2,"Y") -> 30
A6: Id2331 | B6: 1998 | C6: Jul | D6: 27 | E6: 36003 | F6: 0 | G6: 637.26 | H6: tier - 3 | I6: tier - 3 | J6: R1013 | K6: =DATEDIF(Hospitalisation_Details[[#This Row],[Date of Birth]],$L$2,"Y") -> 24
A7: Id2330 | B7: 2001 | C7: Nov | D7: 20 | E7: 37215 | F7: 0 | G7: 646.14 | H7: tier - 3 | I7: tier - 3 | J7: R1012 | K7: =DATEDIF(Hospitalisation_Details[[#This Row],[Date of Birth]],$L$2,"Y") -> 21
A8: Id2329 | B8: 1993 | C8: Jun | D8: 1 | E8: 34121 | F8: 0 | G8: 650 | H8: tier - 3 | I8: tier - 3 | J8: R1013 | K8: =DATEDIF(Hospitalisation_Details[[#This Row],[Date of Birth]],$L$2,"Y") -> 30
A9: Id2328 | B9: 1995 | C9: Jul | D9: 4 | E9: 34884 | F9: 0 | G9: 650 | H9: tier - 3 | I9: tier - 3 | J9: R1013 | K9: =DATEDIF(Hospitalisation_Details[[#This Row],[Date of Birth]],$L$2,"Y") -> 27
A10: Id2327 | B10: 2002 | C10: Nov | D10: 29 | E10: 37589 | F10: 0 | G10: 668 | H10: tier - 3 | I10: tier - 2 | J10: R1012 | K10: =DATEDIF(Hospitalisation_Details[[#This Row],[Date of Birth]],$L$2,"Y") -> 20
A11: Id2326 | B11: 1997 | C11: Nov | D11: 9 | E11: 35743 | F11: 0 | G11: 670 | H11: tier - 3 | I11: tier - 3 | J11: R1013 | K11: =DATEDIF(Hospitalisation_Details[[#This Row],[Date of Birth]],$L$2,"Y") -> 25
A12: Id2325 | B12: 2001 | C12: Sep | D12: 12 | E12: 37146 | F12: 0 | G12: 687.54 | H12: tier - 3 | I12: tier - 2 | J12: R1013 | K12: =DATEDIF(Hospitalisation_Details[[#This Row],[Date of Birth]],$L$2,"Y") -> 21
A13: Id2324 | B13: 1999 | C13: Dec | D13: 26 | E13: 36520 | F13: 0 | G13: 700 | H13: tier - 2 | I13: tier - 3 | J13: R1013 | K13: =DATEDIF(Hospitalisation_Details[[#This Row],[Date of Birth]],$L$2,"Y") -> 23
A14: Id2323 | B14: 1999 | C14: Dec | D14: 14 | E14: 36508 | F14: 0 | G14: 722.99 | H14: tier - 3 | I14: tier - 1 | J14: R1013 | K14: =DATEDIF(Hospitalisation_Details[[#This Row],[Date of Birth]],$L$2,"Y") -> 23
... A2342: Id1 | B2342: 1968 | C2342: Oct | D2342: 12 | E2342: 25123 | F2342: 0 | G2342: 63770.43 | H2342: tier - 1 | I2342: tier - 3 | J2342: R1013 | K2342: =DATEDIF(Hospitalisation_Details[[#This Row],[Date of Birth]],$L$2,"Y") -> 54

Sheet Healthcare-Xlookup
A1: Customer ID | B1: First Name | C1: Last Name | D1: BMI | E1: Weight Status | F1: HBA1C | G1: Diabetes Status | H1: Heart Issue | I1: Any Transplant | J1: Cancer History | K1: No of Major Surgeried | L1: Smoker | M1: Date of Birth | N1: Charges | O1: Hospital Tier | P1: City Tier | Q1: State ID | R1: Age
A2: Id1 | B2: =_xlfn.XLOOKUP(A2,Customer_Names[Customer ID],Customer_Names[First Name],"Not Found") -> Kelly | C2: =_xlfn.XLOOKUP(A2,Customer_Names[Customer ID],Customer_Names[last Name],"Not Found") -> Hawks | D2: =_xlfn.XLOOKUP('Healthcare-Xlookup'!A2,'PWQ_Medical Examinations (2)'!A:A,'PWQ_Medical Examinations (2)'!B:B,"Not Found") -> 47.41 | E2: =_xlfn.XLOOKUP(A2,'PWQ_Medical Examinations (2)'!A:A,'PWQ_Medical Examinations (2)'!C:C,"Not Found") -> Obesity | F2: =_xlfn.XLOOKUP(A2,'PWQ_Medical Examinations (2)'!A:A,'PWQ_Medical Examinations (2)'!D:D,"Not Found") -> 7.47 | G2: =_xlfn.XLOOKUP('Healthcare-Xlookup'!A2,'PWQ_Medical Examinations (2)'!A:A,'PWQ_Medical Examinations (2)'!J:J,"Not Found") -> Diabetes | H2: =_xlfn.XLOOKUP(A2,'PWQ_Medical Examinations (2)'!A:A,'PWQ_Medical Examinations (2)'!E:E,"Not Found") -> No | I2: =_xlfn.XLOOKUP(A2,'PWQ_Medical Examinations (2)'!A:A,'PWQ_Medical Examinations (2)'!F:F,"Not Found") -> No | J2: =_xlfn.XLOOKUP(A2,'PWQ_Medical Examinations (2)'!A:A,'PWQ_Medical Examinations (2)'!G:G,"Not Found") -> No | K2: =_xlfn.XLOOKUP('Healthcare-Xlookup'!A2,'PWQ_Medical Examinations (2)'!A:A,'PWQ_Medical Examinations (2)'!H:H,"Not Found") -> 0 | L2: =_xlfn.XLOOKUP(A2,'PWQ_Medical Examinations (2)'!A:A,'PWQ_Medical Examinations (2)'!I:I,"Not Found") -> yes | M2: =_xlfn.XLOOKUP(A2,'PWQ_Hospitalisation Details (2)'!A:A,'PWQ_Hospitalisation Details (2)'!E:E,"Not Found") -> 25123 | N2: =_xlfn.XLOOKUP(A2,'PWQ_Hospitalisation Details (2)'!A:A,'PWQ_Hospitalisation Details (2)'!G:G,"Not Found") -> 63770.43 | O2: =_xlfn.XLOOKUP(A2,'PWQ_Hospitalisation Details (2)'!A:A,'PWQ_Hospitalisation Details (2)'!H:H,"Not Found") -> tier - 1 | P2: =_xlfn.XLOOKUP(A2,'PWQ_Hospitalisation Details (2)'!A:A,'PWQ_Hospitalisation Details (2)'!I:I,"Not Found") -> tier - 3 | Q2: =_xlfn.XLOOKUP(A2,'PWQ_Hospitalisation Details (2)'!A:A,'PWQ_Hospitalisation Details (2)'!J:J,"Not Found") -> R1013 | R2: =_xlfn.XLOOKUP('Healthcare-Xlookup'!A2,'PWQ_Hospitalisation Details (2)'!A:A,'PWQ_Hospitalisation Details (2)'!K:K,"Not Found") -> 54
A3: Id2 | B3: =_xlfn.XLOOKUP(A3,Customer_Names[Customer ID],Customer_Names[First Name],"Not Found") -> Matthew D | C3: =_xlfn.XLOOKUP(A3,Customer_Names[Customer ID],Customer_Names[last Name],"Not Found") -> Lehner | D3: =_xlfn.XLOOKUP('Healthcare-Xlookup'!A3,'PWQ_Medical Examinations (2)'!A:A,'PWQ_Medical Examinations (2)'!B:B,"Not Found") -> 30.36 | E3: =_xlfn.XLOOKUP(A3,'PWQ_Medical Examinations (2)'!A:A,'PWQ_Medical Examinations (2)'!C:C,"Not Found") -> Obesity | F3: =_xlfn.XLOOKUP(A3,'PWQ_Medical Examinations (2)'!A:A,'PWQ_Medical Examinations (2)'!D:D,"Not Found") -> 5.77 | G3: =_xlfn.XLOOKUP('Healthcare-Xlookup'!A3,'PWQ_Medical Examinations (2)'!A:A,'PWQ_Medical Examinations (2)'!J:J,"Not Found") -> Prediabetes | H3: =_xlfn.XLOOKUP(A3,'PWQ_Medical Examinations (2)'!A:A,'PWQ_Medical Examinations (2)'!E:E,"Not Found") -> No | I3: =_xlfn.XLOOKUP(A3,'PWQ_Medical Examinations (2)'!A:A,'PWQ_Medical Examinations (2)'!F:F,"Not Found") -> No | J3: =_xlfn.XLOOKUP(A3,'PWQ_Medical Examinations (2)'!A:A,'PWQ_Medical Examinations (2)'!G:G,"Not Found") -> No | K3: =_xlfn.XLOOKUP('Healthcare-Xlookup'!A3,'PWQ_Medical Examinations (2)'!A:A,'PWQ_Medical Examinations (2)'!H:H,"Not Found") -> 0 | L3: =_xlfn.XLOOKUP(A3,'PWQ_Medical Examinations (2)'!A:A,'PWQ_Medical Examinations (2)'!I:I,"Not Found") -> yes | M3: =_xlfn.XLOOKUP(A3,'PWQ_Hospitalisation Details (2)'!A:A,'PWQ_Hospitalisation Details (2)'!E:E,"Not Found") -> 28284 | N3: =_xlfn.XLOOKUP(A3,'PWQ_Hospitalisation Details (2)'!A:A,'PWQ_Hospitalisation Details (2)'!G:G,"Not Found") -> 62592.87 | O3: =_xlfn.XLOOKUP(A3,'PWQ_Hospitalisation Details (2)'!A:A,'PWQ_Hospitalisation Details (2)'!H:H,"Not Found") -> tier - 2 | P3: =_xlfn.XLOOKUP(A3,'PWQ_Hospitalisation Details (2)'!A:A,'PWQ_Hospitalisation Details (2)'!I:I,"Not Found") -> tier - 3 | Q3: =_xlfn.XLOOKUP(A3,'PWQ_Hospitalisation Details (2)'!A:A,'PWQ_Hospitalisation Details (2)'!J:J,"Not Found") -> R1013 | R3: =_xlfn.XLOOKUP('Healthcare-Xlookup'!A3,'PWQ_Hospitalisation Details (2)'!A:A,'PWQ_Hospitalisation Details (2)'!K:K,"Not Found") -> 46
A4: Id3 | B4: =_xlfn.XLOOKUP(A4,Customer_Names[Customer ID],Customer_Names[First Name],"Not Found") -> Phil | C4: =_xlfn.XLOOKUP(A4,Customer_Names[Customer ID],Customer_Names[last Name],"Not Found") -> Lu | D4: =_xlfn.XLOOKUP('Healthcare-Xlookup'!A4,'PWQ_Medical Examinations (2)'!A:A,'PWQ_Medical Examinations (2)'!B:B,"Not Found") -> 34.485 | E4: =_xlfn.XLOOKUP(A4,'PWQ_Medical Examinations (2)'!A:A,'PWQ_Medical Examinations (2)'!C:C,"Not Found") -> Obesity | F4: =_xlfn.XLOOKUP(A4,'PWQ_Medical Examinations (2)'!A:A,'PWQ_Medical Examinations (2)'!D:D,"Not Found") -> 11.87 | G4: =_xlfn.XLOOKUP('Healthcare-Xlookup'!A4,'PWQ_Medical Examinations (2)'!A:A,'PWQ_Medical Examinations (2)'!J:J,"Not Found") -> Diabetes | H4: =_xlfn.XLOOKUP(A4,'PWQ_Medical Examinations (2)'!A:A,'PWQ_Medical Examinations (2)'!E:E,"Not Found") -> yes | I4: =_xlfn.XLOOKUP(A4,'PWQ_Medical Examinations (2)'!A:A,'PWQ_Medical Examinations (2)'!F:F,"Not Found") -> No | J4: =_xlfn.XLOOKUP(A4,'PWQ_Medical Examinations (2)'!A:A,'PWQ_Medical Examinations (2)'!G:G,"Not Found") -> No | K4: =_xlfn.XLOOKUP('Healthcare-Xlookup'!A4,'PWQ_Medical Examinations (2)'!A:A,'PWQ_Medical Examinations (2)'!H:H,"Not Found") -> 2 | L4: =_xlfn.XLOOKUP(A4,'PWQ_Medical Examinations (2)'!A:A,'PWQ_Medical Examinations (2)'!I:I,"Not Found") -> yes | M4: =_xlfn.XLOOKUP(A4,'PWQ_Hospitalisation Details (2)'!A:A,'PWQ_Hospitalisation Details (2)'!E:E,"Not Found") -> 25822 | N4: =_xlfn.XLOOKUP(A4,'PWQ_Hospitalisation Details (2)'!A:A,'PWQ_Hospitalisation Details (2)'!G:G,"Not Found") -> 60021.4 | O4: =_xlfn.XLOOKUP(A4,'PWQ_Hospitalisation Details (2)'!A:A,'PWQ_Hospitalisation Details (2)'!H:H,"Not Found") -> tier - 1 | P4: =_xlfn.XLOOKUP(A4,'PWQ_Hospitalisation Details (2)'!A:A,'PWQ_Hospitalisation Details (2)'!I:I,"Not Found") -> tier - 1 | Q4: =_xlfn.XLOOKUP(A4,'PWQ_Hospitalisation Details (2)'!A:A,'PWQ_Hospitalisation Details (2)'!J:J,"Not Found") -> R1012 | R4: =_xlfn.XLOOKUP('Healthcare-Xlookup'!A4,'PWQ_Hospitalisation Details (2)'!A:A,'PWQ_Hospitalisation Details (2)'!K:K,"Not Found") -> 52
A5: Id4 | B5: =_xlfn.XLOOKUP(A5,Customer_Names[Customer ID],Customer_Names[First Name],"Not Found") -> Kelsey | C5: =_xlfn.XLOOKUP(A5,Customer_Names[Customer ID],Customer_Names[last Name],"Not Found") -> Osborne | D5: =_xlfn.XLOOKUP('Healthcare-Xlookup'!A5,'PWQ_Medical Examinations (2)'!A:A,'PWQ_Medical Examinations (2)'!B:B,"Not Found") -> 38.095 | E5: =_xlfn.XLOOKUP(A5,'PWQ_Medical Examinations (2)'!A:A,'PWQ_Medical Examinations (2)'!C:C,"Not Found") -> Obesity | F5: =_xlfn.XLOOKUP(A5,'PWQ_Medical Examinations (2)'!A:A,'PWQ_Medical Examinations (2)'!D:D,"Not Found") -> 6.05 | G5: =_xlfn.XLOOKUP('Healthcare-Xlookup'!A5,'PWQ_Medical Examinations (2)'!A:A,'PWQ_Medical Examinations (2)'!J:J,"Not Found") -> Prediabetes | H5: =_xlfn.XLOOKUP(A5,'PWQ_Medical Examinations (2)'!A:A,'PWQ_Medical Examinations (2)'!E:E,"Not Found") -> No | I5: =_xlfn.XLOOKUP(A5,'PWQ_Medical Examinations (2)'!A:A,'PWQ_Medical Examinations (2)'!F:F,"Not Found") -> No | J5: =_xlfn.XLOOKUP(A5,'PWQ_Medical Examinations (2)'!A:A,'PWQ_Medical Examinations (2)'!G:G,"Not Found") -> No | K5: =_xlfn.XLOOKUP('Healthcare-Xlookup'!A5,'PWQ_Medical Examinations (2)'!A:A,'PWQ_Medical Examinations (2)'!H:H,"Not Found") -> 0 | L5: =_xlfn.XLOOKUP(A5,'PWQ_Medical Examinations (2)'!A:A,'PWQ_Medical Examinations (2)'!I:I,"Not Found") -> yes | M5: =_xlfn.XLOOKUP(A5,'PWQ_Hospitalisation Details (2)'!A:A,'PWQ_Hospitalisation Details (2)'!E:E,"Not Found") -> 33395 | N5: =_xlfn.XLOOKUP(A5,'PWQ_Hospitalisation Details (2)'!A:A,'PWQ_Hospitalisation Details (2)'!G:G,"Not Found") -> 58571.07 | O5: =_xlfn.XLOOKUP(A5,'PWQ_Hospitalisation Details (2)'!A:A,'PWQ_Hospitalisation Details (2)'!H:H,"Not Found") -> tier - 1 | P5: =_xlfn.XLOOKUP(A5,'PWQ_Hospitalisation Details (2)'!A:A,'PWQ_Hospitalisation Details (2)'!I:I,"Not Found") -> tier - 3 | Q5: =_xlfn.XLOOKUP(A5,'PWQ_Hospitalisation Details (2)'!A:A,'PWQ_Hospitalisation Details (2)'!J:J,"Not Found") -> R1024 | R5: =_xlfn.XLOOKUP('Healthcare-Xlookup'!A5,'PWQ_Hospitalisation Details (2)'!A:A,'PWQ_Hospitalisation Details (2)'!K:K,"Not Found") -> 32
A6: Id5 | B6: =_xlfn.XLOOKUP(A6,Customer_Names[Customer ID],Customer_Names[First Name],"Not Found") -> Kristyn | C6: =_xlfn.XLOOKUP(A6,Customer_Names[Customer ID],Customer_Names[last Name],"Not Found") -> Kadala | D6: =_xlfn.XLOOKUP('Healthcare-Xlookup'!A6,'PWQ_Medical Examinations (2)'!A:A,'PWQ_Medical Examinations (2)'!B:B,"Not Found") -> 35.53 | E6: =_xlfn.XLOOKUP(A6,'PWQ_Medical Examinations (2)'!A:A,'PWQ_Medical Examinations (2)'!C:C,"Not Found") -> Obesity | F6: =_xlfn.XLOOKUP(A6,'PWQ_Medical Examinations (2)'!A:A,'PWQ_Medical Examinations (2)'!D:D,"Not Found") -> 5.45 | G6: =_xlfn.XLOOKUP('Healthcare-Xlookup'!A6,'PWQ_Medical Examinations (2)'!A:A,'PWQ_Medical Examinations (2)'!J:J,"Not Found") -> Normal | H6: =_xlfn.XLOOKUP(A6,'PWQ_Medical Examinations (2)'!A:A,'PWQ_Medical Examinations (2)'!E:E,"Not Found") -> No | I6: =_xlfn.XLOOKUP(A6,'PWQ_Medical Examinations (2)'!A:A,'PWQ_Medical Examinations (2)'!F:F,"Not Found") -> No | J6: =_xlfn.XLOOKUP(A6,'PWQ_Medical Examinations (2)'!A:A,'PWQ_Medical Examinations (2)'!G:G,"Not Found") -> No | K6: =_xlfn.XLOOKUP('Healthcare-Xlookup'!A6,'PWQ_Medical Examinations (2)'!A:A,'PWQ_Medical Examinations (2)'!H:H,"Not Found") -> 0 | L6: =_xlfn.XLOOKUP(A6,'PWQ_Medical Examinations (2)'!A:A,'PWQ_Medical Examinations (2)'!I:I,"Not Found") -> yes | M6: =_xlfn.XLOOKUP(A6,'PWQ_Hospitalisation Details (2)'!A:A,'PWQ_Hospitalisation Details (2)'!E:E,"Not Found") -> 32678 | N6: =_xlfn.XLOOKUP(A6,'PWQ_Hospitalisation Details (2)'!A:A,'PWQ_Hospitalisation Details (2)'!G:G,"Not Found") -> 55135.4 | O6: =_xlfn.XLOOKUP(A6,'PWQ_Hospitalisation Details (2)'!A:A,'PWQ_Hospitalisation Details (2)'!H:H,"Not Found") -> tier - 1 | P6: =_xlfn.XLOOKUP(A6,'PWQ_Hospitalisation Details (2)'!A:A,'PWQ_Hospitalisation Details (2)'!I:I,"Not Found") -> tier - 2 | Q6: =_xlfn.XLOOKUP(A6,'PWQ_Hospitalisation Details (2)'!A:A,'PWQ_Hospitalisation Details (2)'!J:J,"Not Found") -> R1012 | R6: =_xlfn.XLOOKUP('Healthcare-Xlookup'!A6,'PWQ_Hospitalisation Details (2)'!A:A,'PWQ_Hospitalisation Details (2)'!K:K,"Not Found") -> 33
A7: Id6 | B7: =_xlfn.XLOOKUP(A7,Customer_Names[Customer ID],Customer_Names[First Name],"Not Found") -> Russell B | C7: =_xlfn.XLOOKUP(A7,Customer_Names[Customer ID],Customer_Names[last Name],"Not Found") -> Baker | D7: =_xlfn.XLOOKUP('Healthcare-Xlookup'!A7,'PWQ_Medical Examinations (2)'!A:A,'PWQ_Medical Examinations (2)'!B:B,"Not Found") -> 32.8 | E7: =_xlfn.XLOOKUP(A7,'PWQ_Medical Examinations (2)'!A:A,'PWQ_Medical Examinations (2)'!C:C,"Not Found") -> Obesity | F7: =_xlfn.XLOOKUP(A7,'PWQ_Medical Examinations (2)'!A:A,'PWQ_Medical Examinations (2)'!D:D,"Not Found") -> 6.59 | G7: =_xlfn.XLOOKUP('Healthcare-Xlookup'!A7,'PWQ_Medical Examinations (2)'!A:A,'PWQ_Medical Examinations (2)'!J:J,"Not Found") -> Diabetes | H7: =_xlfn.XLOOKUP(A7,'PWQ_Medical Examinations (2)'!A:A,'PWQ_Medical Examinations (2)'!E:E,"Not Found") -> No | I7: =_xlfn.XLOOKUP(A7,'PWQ_Medical Examinations (2)'!A:A,'PWQ_Medical Examinations (2)'!F:F,"Not Found") -> No | J7: =_xlfn.XLOOKUP(A7,'PWQ_Medical Examinations (2)'!A:A,'PWQ_Medical Examinations (2)'!G:G,"Not Found") -> No | K7: =_xlfn.XLOOKUP('Healthcare-Xlookup'!A7,'PWQ_Medical Examinations (2)'!A:A,'PWQ_Medical Examinations (2)'!H:H,"Not Found") -> 0 | L7: =_xlfn.XLOOKUP(A7,'PWQ_Medical Examinations (2)'!A:A,'PWQ_Medical Examinations (2)'!I:I,"Not Found") -> yes | M7: =_xlfn.XLOOKUP(A7,'PWQ_Hospitalisation Details (2)'!A:A,'PWQ_Hospitalisation Details (2)'!E:E,"Not Found") -> 22862 | N7: =_xlfn.XLOOKUP(A7,'PWQ_Hospitalisation Details (2)'!A:A,'PWQ_Hospitalisation Details (2)'!G:G,"Not Found") -> 52590.83 | O7: =_xlfn.XLOOKUP(A7,'PWQ_Hospitalisation Details (2)'!A:A,'PWQ_Hospitalisation Details (2)'!H:H,"Not Found") -> tier - 1 | P7: =_xlfn.XLOOKUP(A7,'PWQ_Hospitalisation Details (2)'!A:A,'PWQ_Hospitalisation Details (2)'!I:I,"Not Found") -> tier - 3 | Q7: =_xlfn.XLOOKUP(A7,'PWQ_Hospitalisation Details (2)'!A:A,'PWQ_Hospitalisation Details (2)'!J:J,"Not Found") -> R1011 | R7: =_xlfn.XLOOKUP('Healthcare-Xlookup'!A7,'PWQ_Hospitalisation Details (2)'!A:A,'PWQ_Hospitalisation Details (2)'!K:K,"Not Found") -> 60
A8: Id7 | B8: =_xlfn.XLOOKUP(A8,Customer_Names[Customer ID],Customer_Names[First Name],"Not Found") -> Scott | C8: =_xlfn.XLOOKUP(A8,Customer_Names[Customer ID],Customer_Names[last Name],"Not Found") -> Macpherson | D8: =_xlfn.XLOOKUP('Healthcare-Xlookup'!A8,'PWQ_Medical Examinations (2)'!A:A,'PWQ_Medical Examinations (2)'!B:B,"Not Found") -> 36.4 | E8: =_xlfn.XLOOKUP(A8,'PWQ_Medical Examinations (2)'!A:A,'PWQ_Medical Examinations (2)'!C:C,"Not Found") -> Obesity | F8: =_xlfn.XLOOKUP(A8,'PWQ_Medical Examinations (2)'!A:A,'PWQ_Medical Examinations (2)'!D:D,"Not Found") -> 6.07 | G8: =_xlfn.XLOOKUP('Healthcare-Xlookup'!A8,'PWQ_Medical Examinations (2)'!A:A,'PWQ_Medical Examinations (2)'!J:J,"Not Found") -> Prediabetes | H8: =_xlfn.XLOOKUP(A8,'PWQ_Medical Examinations (2)'!A:A,'PWQ_Medical Examinations (2)'!E:E,"Not Found") -> No | I8: =_xlfn.XLOOKUP(A8,'PWQ_Medical Examinations (2)'!A:A,'PWQ_Medical Examinations (2)'!F:F,"Not Found") -> No | J8: =_xlfn.XLOOKUP(A8,'PWQ_Medical Examinations (2)'!A:A,'PWQ_Medical Examinations (2)'!G:G,"Not Found") -> No | K8: =_xlfn.XLOOKUP('Healthcare-Xlookup'!A8,'PWQ_Medical Examinations (2)'!A:A,'PWQ_Medical Examinations (2)'!H:H,"Not Found") -> 0 | L8: =_xlfn.XLOOKUP(A8,'PWQ_Medical Examinations (2)'!A:A,'PWQ_Medical Examinations (2)'!I:I,"Not Found") -> yes | M8: =_xlfn.XLOOKUP(A8,'PWQ_Hospitalisation Details (2)'!A:A,'PWQ_Hospitalisation Details (2)'!E:E,"Not Found") -> 34634 | N8: =_xlfn.XLOOKUP(A8,'PWQ_Hospitalisation Details (2)'!A:A,'PWQ_Hospitalisation Details (2)'!G:G,"Not Found") -> 51194.56 | O8: =_xlfn.XLOOKUP(A8,'PWQ_Hospitalisation Details (2)'!A:A,'PWQ_Hospitalisation Details (2)'!H:H,"Not Found") -> tier - 1 | P8: =_xlfn.XLOOKUP(A8,'PWQ_Hospitalisation Details (2)'!A:A,'PWQ_Hospitalisation Details (2)'!I:I,"Not Found") -> tier - 3 | Q8: =_xlfn.XLOOKUP(A8,'PWQ_Hospitalisation Details (2)'!A:A,'PWQ_Hospitalisation Details (2)'!J:J,"Not Found") -> R1011 | R8: =_xlfn.XLOOKUP('Healthcare-Xlookup'!A8,'PWQ_Hospitalisation Details (2)'!A:A,'PWQ_Hospitalisation Details (2)'!K:K,"Not Found") -> 28
A9: Id8 | B9: =_xlfn.XLOOKUP(A9,Customer_Names[Customer ID],Customer_Names[First Name],"Not Found") -> Stephen | C9: =_xlfn.XLOOKUP(A9,Customer_Names[Customer ID],Customer_Names[last Name],"Not Found") -> Hallman | D9: =_xlfn.XLOOKUP('Healthcare-Xlookup'!A9,'PWQ_Medical Examinations (2)'!A:A,'PWQ_Medical Examinations (2)'!B:B,"Not Found") -> 36.96 | E9: =_xlfn.XLOOKUP(A9,'PWQ_Medical Examinations (2)'!A:A,'PWQ_Medical Examinations (2)'!C:C,"Not Found") -> Obesity | F9: =_xlfn.XLOOKUP(A9,'PWQ_Medical Examinations (2)'!A:A,'PWQ_Medical Examinations (2)'!D:D,"Not Found") -> 7.93 | G9: =_xlfn.XLOOKUP('Healthcare-Xlookup'!A9,'PWQ_Medical Examinations (2)'!A:A,'PWQ_Medical Examinations (2)'!J:J,"Not Found") -> Diabetes | H9: =_xlfn.XLOOKUP(A9,'PWQ_Medical Examinations (2)'!A:A,'PWQ_Medical Examinations (2)'!E:E,"Not Found") -> No | I9: =_xlfn.XLOOKUP(A9,'PWQ_Medical Examinations (2)'!A:A,'PWQ_Medical Examinations (2)'!F:F,"Not Found") -> No | J9: =_xlfn.XLOOKUP(A9,'PWQ_Medical Examinations (2)'!A:A,'PWQ_Medical Examinations (2)'!G:G,"Not Found") -> No | K9: =_xlfn.XLOOKUP('Healthcare-Xlookup'!A9,'PWQ_Medical Examinations (2)'!A:A,'PWQ_Medical Examinations (2)'!H:H,"Not Found") -> 3 | L9: =_xlfn.XLOOKUP(A9,'PWQ_Medical Examinations (2)'!A:A,'PWQ_Medical Examinations (2)'!I:I,"Not Found") -> yes | M9: =_xlfn.XLOOKUP(A9,'PWQ_Hospitalisation Details (2)'!A:A,'PWQ_Hospitalisation Details (2)'!E:E,"Not Found") -> 21363 | N9: =_xlfn.XLOOKUP(A9,'PWQ_Hospitalisation Details (2)'!A:A,'PWQ_Hospitalisation Details (2)'!G:G,"Not Found") -> 49577.66 | O9: =_xlfn.XLOOKUP(A9,'PWQ_Hospitalisation Details (2)'!A:A,'PWQ_Hospitalisation Details (2)'!H:H,"Not Found") -> tier - 2 | P9: =_xlfn.XLOOKUP(A9,'PWQ_Hospitalisation Details (2)'!A:A,'PWQ_Hospitalisation Details (2)'!I:I,"Not Found") -> tier - 2 | Q9: =_xlfn.XLOOKUP(A9,'PWQ_Hospitalisation Details (2)'!A:A,'PWQ_Hospitalisation Details (2)'!J:J,"Not Found") -> R1013 | R9: =_xlfn.XLOOKUP('Healthcare-Xlookup'!A9,'PWQ_Hospitalisation Details (2)'!A:A,'PWQ_Hospitalisation Details (2)'!K:K,"Not Found") -> 64
A10: Id9 | B10: =_xlfn.XLOOKUP(A10,Customer_Names[Customer ID],Customer_Names[First Name],"Not Found") -> Patrick R | C10: =_xlfn.XLOOKUP(A10,Customer_Names[Customer ID],Customer_Names[last Name],"Not Found") -> Moran | D10: =_xlfn.XLOOKUP('Healthcare-Xlookup'!A10,'PWQ_Medical Examinations (2)'!A:A,'PWQ_Medical Examinations (2)'!B:B,"Not Found") -> 41.14 | E10: =_xlfn.XLOOKUP(A10,'PWQ_Medical Examinations (2)'!A:A,'PWQ_Medical Examinations (2)'!C:C,"Not Found") -> Obesity | F10: =_xlfn.XLOOKUP(A10,'PWQ_Medical Examinations (2)'!A:A,'PWQ_Medical Examinations (2)'!D:D,"Not Found") -> 9.58 | G10: =_xlfn.XLOOKUP('Healthcare-Xlookup'!A10,'PWQ_Medical Examinations (2)'!A:A,'PWQ_Medical Examinations (2)'!J:J,"Not Found") -> Diabetes | H10: =_xlfn.XLOOKUP(A10,'PWQ_Medical Examinations (2)'!A:A,'PWQ_Medical Examinations (2)'!E:E,"Not Found") -> yes | I10: =_xlfn.XLOOKUP(A10,'PWQ_Medical Examinations (2)'!A:A,'PWQ_Medical Examinations (2)'!F:F,"Not Found") -> No | J10: =_xlfn.XLOOKUP(A10,'PWQ_Medical Examinations (2)'!A:A,'PWQ_Medical Examinations (2)'!G:G,"Not Found") -> Yes | K10: =_xlfn.XLOOKUP('Healthcare-Xlookup'!A10,'PWQ_Medical Examinations (2)'!A:A,'PWQ_Medical Examinations (2)'!H:H,"Not Found") -> 1 | L10: =_xlfn.XLOOKUP(A10,'PWQ_Medical Examinations (2)'!A:A,'PWQ_Medical Examinations (2)'!I:I,"Not Found") -> yes | M10: =_xlfn.XLOOKUP(A10,'PWQ_Hospitalisation Details (2)'!A:A,'PWQ_Hospitalisation Details (2)'!E:E,"Not Found") -> 23258 | N10: =_xlfn.XLOOKUP(A10,'PWQ_Hospitalisation Details (2)'!A:A,'PWQ_Hospitalisation Details (2)'!G:G,"Not Found") -> 48970.25 | O10: =_xlfn.XLOOKUP(A10,'PWQ_Hospitalisation Details (2)'!A:A,'PWQ_Hospitalisation Details (2)'!H:H,"Not Found") -> tier - 1 | P10: =_xlfn.XLOOKUP(A10,'PWQ_Hospitalisation Details (2)'!A:A,'PWQ_Hospitalisation Details (2)'!I:I,"Not Found") -> tier - 2 | Q10: =_xlfn.XLOOKUP(A10,'PWQ_Hospitalisation Details (2)'!A:A,'PWQ_Hospitalisation Details (2)'!J:J,"Not Found") -> R1013 | R10: =_xlfn.XLOOKUP('Healthcare-Xlookup'!A10,'PWQ_Hospitalisation Details (2)'!A:A,'PWQ_Hospitalisation Details (2)'!K:K,"Not Found") -> 59
A11: Id10 | B11: =_xlfn.XLOOKUP(A11,Customer_Names[Customer ID],Customer_Names[First Name],"Not Found") -> Brooke N | C11: =_xlfn.XLOOKUP(A11,Customer_Names[Customer ID],Customer_Names[last Name],"Not Found") -> Benner | D11: =_xlfn.XLOOKUP('Healthcare-Xlookup'!A11,'PWQ_Medical Examinations (2)'!A:A,'PWQ_Medical Examinations (2)'!B:B,"Not Found") -> 38.06 | E11: =_xlfn.XLOOKUP(A11,'PWQ_Medical Examinations (2)'!A:A,'PWQ_Medical Examinations (2)'!C:C,"Not Found") -> Obesity | F11: =_xlfn.XLOOKUP(A11,'PWQ_Medical Examinations (2)'!A:A,'PWQ_Medical Examinations (2)'!D:D,"Not Found") -> 10.79 | G11: =_xlfn.XLOOKUP('Healthcare-Xlookup'!A11,'PWQ_Medical Examinations (2)'!A:A,'PWQ_Medical Examinations (2)'!J:J,"Not Found") -> Diabetes | H11: =_xlfn.XLOOKUP(A11,'PWQ_Medical Examinations (2)'!A:A,'PWQ_Medical Examinations (2)'!E:E,"Not Found") -> No | I11: =_xlfn.XLOOKUP(A11,'PWQ_Medical Examinations (2)'!A:A,'PWQ_Medical Examinations (2)'!F:F,"Not Found") -> No | J11: =_xlfn.XLOOKUP(A11,'PWQ_Medical Examinations (2)'!A:A,'PWQ_Medical Examinations (2)'!G:G,"Not Found") -> No | K11: =_xlfn.XLOOKUP('Healthcare-Xlookup'!A11,'PWQ_Medical Examinations (2)'!A:A,'PWQ_Medical Examinations (2)'!H:H,"Not Found") -> 0 | L11: =_xlfn.XLOOKUP(A11,'PWQ_Medical Examinations (2)'!A:A,'PWQ_Medical Examinations (2)'!I:I,"Not Found") -> yes | M11: =_xlfn.XLOOKUP(A11,'PWQ_Hospitalisation Details (2)'!A:A,'PWQ_Hospitalisation Details (2)'!E:E,"Not Found") -> 28853 | N11: =_xlfn.XLOOKUP(A11,'PWQ_Hospitalisation Details (2)'!A:A,'PWQ_Hospitalisation Details (2)'!G:G,"Not Found") -> 48885.14 | O11: =_xlfn.XLOOKUP(A11,'PWQ_Hospitalisation Details (2)'!A:A,'PWQ_Hospitalisation Details (2)'!H:H,"Not Found") -> tier - 1 | P11: =_xlfn.XLOOKUP(A11,'PWQ_Hospitalisation Details (2)'!A:A,'PWQ_Hospitalisation Details (2)'!I:I,"Not Found") -> tier - 2 | Q11: =_xlfn.XLOOKUP(A11,'PWQ_Hospitalisation Details (2)'!A:A,'PWQ_Hospitalisation Details (2)'!J:J,"Not Found") -> R1013 | R11: =_xlfn.XLOOKUP('Healthcare-Xlookup'!A11,'PWQ_Hospitalisation Details (2)'!A:A,'PWQ_Hospitalisation Details (2)'!K:K,"Not Found") -> 44
A12: Id11 | B12: =_xlfn.XLOOKUP(A12,Customer_Names[Customer ID],Customer_Names[First Name],"Not Found") -> Paola Andrea | C12: =_xlfn.XLOOKUP(A12,Customer_Names[Customer ID],Customer_Names[last Name],"Not Found") -> Fierro Vargas | D12: =_xlfn.XLOOKUP('Healthcare-Xlookup'!A12,'PWQ_Medical Examinations (2)'!A:A,'PWQ_Medical Examinations (2)'!B:B,"Not Found") -> 37.7 | E12: =_xlfn.XLOOKUP(A12,'PWQ_Medical Examinations (2)'!A:A,'PWQ_Medical Examinations (2)'!C:C,"Not Found") -> Obesity | F12: =_xlfn.XLOOKUP(A12,'PWQ_Medical Examinations (2)'!A:A,'PWQ_Medical Examinations (2)'!D:D,"Not Found") -> 5.96 | G12: =_xlfn.XLOOKUP('Healthcare-Xlookup'!A12,'PWQ_Medical Examinations (2)'!A:A,'PWQ_Medical Examinations (2)'!J:J,"Not Found") -> Prediabetes | H12: =_xlfn.XLOOKUP(A12,'PWQ_Medical Examinations (2)'!A:A,'PWQ_Medical Examinations (2)'!E:E,"Not Found") -> yes | I12: =_xlfn.XLOOKUP(A12,'PWQ_Medical Examinations (2)'!A:A,'PWQ_Medical Examinations (2)'!F:F,"Not Found") -> No | J12: =_xlfn.XLOOKUP(A12,'PWQ_Medical Examinations (2)'!A:A,'PWQ_Medical Examinations (2)'!G:G,"Not Found") -> No | K12: =_xlfn.XLOOKUP('Healthcare-Xlookup'!A12,'PWQ_Medical Examinations (2)'!A:A,'PWQ_Medical Examinations (2)'!H:H,"Not Found") -> 2 | L12: =_xlfn.XLOOKUP(A12,'PWQ_Medical Examinations (2)'!A:A,'PWQ_Medical Examinations (2)'!I:I,"Not Found") -> yes | M12: =_xlfn.XLOOKUP(A12,'PWQ_Hospitalisation Details (2)'!A:A,'PWQ_Hospitalisation Details (2)'!E:E,"Not Found") -> 21753 | N12: =_xlfn.XLOOKUP(A12,'PWQ_Hospitalisation Details (2)'!A:A,'PWQ_Hospitalisation Details (2)'!G:G,"Not Found") -> 48824.45 | O12: =_xlfn.XLOOKUP(A12,'PWQ_Hospitalisation Details (2)'!A:A,'PWQ_Hospitalisation Details (2)'!H:H,"Not Found") -> tier - 2 | P12: =_xlfn.XLOOKUP(A12,'PWQ_Hospitalisation Details (2)'!A:A,'PWQ_Hospitalisation Details (2)'!I:I,"Not Found") -> tier - 1 | Q12: =_xlfn.XLOOKUP(A12,'PWQ_Hospitalisation Details (2)'!A:A,'PWQ_Hospitalisation Details (2)'!J:J,"Not Found") -> R1011 | R12: =_xlfn.XLOOKUP('Healthcare-Xlookup'!A12,'PWQ_Hospitalisation Details (2)'!A:A,'PWQ_Hospitalisation Details (2)'!K:K,"Not Found") -> 63
A13: Id12 | B13: =_xlfn.XLOOKUP(A13,Customer_Names[Customer ID],Customer_Names[First Name],"Not Found") -> David | C13: =_xlfn.XLOOKUP(A13,Customer_Names[Customer ID],Customer_Names[last Name],"Not Found") -> Franz | D13: =_xlfn.XLOOKUP('Healthcare-Xlookup'!A13,'PWQ_Medical Examinations (2)'!A:A,'PWQ_Medical Examinations (2)'!B:B,"Not Found") -> 42.13 | E13: =_xlfn.XLOOKUP(A13,'PWQ_Medical Examinations (2)'!A:A,'PWQ_Medical Examinations (2)'!C:C,"Not Found") -> Obesity | F13: =_xlfn.XLOOKUP(A13,'PWQ_Medical Examinations (2)'!A:A,'PWQ_Medical Examinations (2)'!D:D,"Not Found") -> 11.9 | G13: =_xlfn.XLOOKUP('Healthcare-Xlookup'!A13,'PWQ_Medical Examinations (2)'!A:A,'PWQ_Medical Examinations (2)'!J:J,"Not Found") -> Diabetes | H13: =_xlfn.XLOOKUP(A13,'PWQ_Medical Examinations (2)'!A:A,'PWQ_Medical Examinations (2)'!E:E,"Not Found") -> No | I13: =_xlfn.XLOOKUP(A13,'PWQ_Medical Examinations (2)'!A:A,'PWQ_Medical Examinations (2)'!F:F,"Not Found") -> No | J13: =_xlfn.XLOOKUP(A13,'PWQ_Medical Examinations (2)'!A:A,'PWQ_Medical Examinations (2)'!G:G,"Not Found") -> No | K13: =_xlfn.XLOOKUP('Healthcare-Xlookup'!A13,'PWQ_Medical Examinations (2)'!A:A,'PWQ_Medical Examinations (2)'!H:H,"Not Found") -> 0 | L13: =_xlfn.XLOOKUP(A13,'PWQ_Medical Examinations (2)'!A:A,'PWQ_Medical Examinations (2)'!I:I,"Not Found") -> yes | M13: =_xlfn.XLOOKUP(A13,'PWQ_Hospitalisation Details (2)'!A:A,'PWQ_Hospitalisation Details (2)'!E:E,"Not Found") -> 24042 | N13: =_xlfn.XLOOKUP(A13,'PWQ_Hospitalisation Details (2)'!A:A,'PWQ_Hospitalisation Details (2)'!G:G,"Not Found") -> 48675.52 | O13: =_xlfn.XLOOKUP(A13,'PWQ_Hospitalisation Details (2)'!A:A,'PWQ_Hospitalisation Details (2)'!H:H,"Not Found") -> tier - 1 | P13: =_xlfn.XLOOKUP(A13,'PWQ_Hospitalisation Details (2)'!A:A,'PWQ_Hospitalisation Details (2)'!I:I,"Not Found") -> tier - 2 | Q13: =_xlfn.XLOOKUP(A13,'PWQ_Hospitalisation Details (2)'!A:A,'PWQ_Hospitalisation Details (2)'!J:J,"Not Found") -> R1013 | R13: =_xlfn.XLOOKUP('Healthcare-Xlookup'!A13,'PWQ_Hospitalisation Details (2)'!A:A,'PWQ_Hospitalisation Details (2)'!K:K,"Not Found") -> 57
... A2336: Id2335 | B2336: =_xlfn.XLOOKUP(A2336,Customer_Names[Customer ID],Customer_Names[First Name],"Not Found") -> Aaron K | C2336: =_xlfn.XLOOKUP(A2336,Customer_Names[Customer ID],Customer_Names[last Name],"Not Found") -> German | D2336: =_xlfn.XLOOKUP('Healthcare-Xlookup'!A2336,'PWQ_Medical Examinations (2)'!A:A,'PWQ_Medical Examinations (2)'!B:B,"Not Found") -> 17.58 | E2336: =_xlfn.XLOOKUP(A2336,'PWQ_Medical Examinations (2)'!A:A,'PWQ_Medical Examinations (2)'!C:C,"Not Found") -> Under Weight | F2336: =_xlfn.XLOOKUP(A2336,'PWQ_Medical Examinations (2)'!A:A,'PWQ_Medical Examinations (2)'!D:D,"Not Found") -> 4.51 | G2336: =_xlfn.XLOOKUP('Healthcare-Xlookup'!A2336,'PWQ_Medical Examinations (2)'!A:A,'PWQ_Medical Examinations (2)'!J:J,"Not Found") -> Normal | H2336: =_xlfn.XLOOKUP(A2336,'PWQ_Medical Examinations (2)'!A:A,'PWQ_Medical Examinations (2)'!E:E,"Not Found") -> No | I2336: =_xlfn.XLOOKUP(A2336,'PWQ_Medical Examinations (2)'!A:A,'PWQ_Medical Examinations (2)'!F:F,"Not Found") -> No | J2336: =_xlfn.XLOOKUP(A2336,'PWQ_Medical Examinations (2)'!A:A,'PWQ_Medical Examinations (2)'!G:G,"Not Found") -> No | K2336: =_xlfn.XLOOKUP('Healthcare-Xlookup'!A2336,'PWQ_Medical Examinations (2)'!A:A,'PWQ_Medical Examinations (2)'!H:H,"Not Found") -> 1 | L2336: =_xlfn.XLOOKUP(A2336,'PWQ_Medical Examinations (2)'!A:A,'PWQ_Medical Examinations (2)'!I:I,"Not Found") -> No | M2336: =_xlfn.XLOOKUP(A2336,'PWQ_Hospitalisation Details (2)'!A:A,'PWQ_Hospitalisation Details (2)'!E:E,"Not Found") -> 33794 | N2336: =_xlfn.XLOOKUP(A2336,'PWQ_Hospitalisation Details (2)'!A:A,'PWQ_Hospitalisation Details (2)'!G:G,"Not Found") -> 563.84 | O2336: =_xlfn.XLOOKUP(A2336,'PWQ_Hospitalisation Details (2)'!A:A,'PWQ_Hospitalisation Details (2)'!H:H,"Not Found") -> tier - 2 | P2336: =_xlfn.XLOOKUP(A2336,'PWQ_Hospitalisation Details (2)'!A:A,'PWQ_Hospitalisation Details (2)'!I:I,"Not Found") -> tier - 3 | Q2336: =_xlfn.XLOOKUP(A2336,'PWQ_Hospitalisation Details (2)'!A:A,'PWQ_Hospitalisation Details (2)'!J:J,"Not Found") -> R1013 | R2336: =_xlfn.XLOOKUP('Healthcare-Xlookup'!A2336,'PWQ_Hospitalisation Details (2)'!A:A,'PWQ_Hospitalisation Details (2)'!K:K,"Not Found") -> 30

Sheet Sheet1
A3: Row Labels | B3: Count of Heart Issue
A4: 18 | B4: 55
A5: 19 | B5: 43
A6: 20 | B6: 25
A7: 21 | B7: 18
A8: 22 | B8: 32
A9: 23 | B9: 28
A10: 24 | B10: 18
A11: 25 | B11: 28
A12: 26 | B12: 21
A13: 27 | B13: 28
A14: 28 | B14: 30
A15: 29 | B15: 28
... A20: 34 | B20: 30
A21: 35 | B21: 20 | E21: Row Labels | F21: Sum of HBA1C | G21: Count of Customer ID
A22: 36 | B22: 17 | E22: Diabetes | F22: 7381.86 | G22: 797
A23: 37 | B23: 25 | E23: Normal | F23: 5309.95 | G23: 1095
A24: 38 | B24: 17 | E24: Prediabetes | F24: 2670.15 | G24: 443
A25: 39 | B25: 20 | E25: (blank)
A26: 40 | B26: 25 | E26: Grand Total | F26: 15361.96 | G26: 2335
A27: 41 | B27: 30
A28: 42 | B28: 20
A29: 43 | B29: 28
A30: 44 | B30: 24
A31: 45 | B31: 23
A32: 46 | B32: 29
A33: 47 | B33: 26
A34: 48 | B34: 35
A35: 49 | B35: 22
A36: 50 | B36: 28
A37: 51 | B37: 32
A38: 52 | B38: 35
... A50: 64 | B50: 17
A51: Grand Total | B51: 1221
F54: \ | G54: Sum of Charges
F55: tier - 1 | G55: 6953519.3
A56: \ | B56: Sum of Charges | F56: tier - 2 | G56: 9654966.3
A57: tier - 1 | B57: 6953519.3 | F57: tier - 3 | G57: 3735161.2
A58: tier - 2 | B58: 9654966.3 | F58: Grand Total | G58: 20343647
A59: tier - 3 | B59: 3735161.2 | I59: Row Labels | J59: Count of Customer ID
...

Sheet Sheet2
A3: Row Labels | B3: Count of Customer ID
A4: Not Found | B4: 2
A5: tier - 1 | B5: 731
A6: tier - 2 | B6: 809
A7: tier - 3 | B7: 793
A8: Grand Total | B8: 2335
A10: Row Labels | B10: Sum of Charges
A11: R1011 | B11: 11173625
A12: R1012 | B12: 6909472.5
A13: R1013 | B13: 6426595.5
A14: R1014 | B14: 175214.74
A15: R1015 | B15: 167383.32
A16: R1016 | B16: 869712.86
A17: R1017 | B17: 533019.88
A18: R1018 | B18: 119455.08
A19: R1019 | B19: 354461.73
A20: R1020 | B20: 55430.99
A21: R1021 | B21: 625336.47
A22: R1022 | B22: 149107.3
... A28: Grand Total | B28: 31575976

Sheet Healthcare
A1: Customer ID | B1: First Name | C1: Last Name | D1: BMI | E1: Weight Status | F1: HBA1C | G1: Diabetes Status | H1: Heart Issue | I1: Any Transplant | J1: Cancer History | K1: No of Major Surgeries | L1: Smoker | M1: Date of Birth | N1: Charges | O1: Hospital Tier | P1: City Tier | Q1: State ID | R1: Age
A2: Id1 | B2: Kelly | C2: Hawks | D2: 47.41 | E2: Obesity | F2: 7.47 | G2: Diabetes | H2: No | I2: No | J2: No | K2: 0 | L2: =_xlfn.XLOOKUP(A2,'PWQ_Medical Examinations (2)'!A:A,'PWQ_Medical Examinations (2)'!I:I,"Not Found") -> yes | M2: 25123 | N2: 63770.43 | O2: tier - 1 | P2: tier - 3 | Q2: R1013 | R2: 54
A3: Id2 | B3: Matthew D | C3: Lehner | D3: 30.36 | E3: Obesity | F3: 5.77 | G3: Prediabetes | H3: No | I3: No | J3: No | K3: 0 | L3: =_xlfn.XLOOKUP(A3,'PWQ_Medical Examinations (2)'!A:A,'PWQ_Medical Examinations (2)'!I:I,"Not Found") -> yes | M3: 28284 | N3: 62592.87 | O3: tier - 2 | P3: tier - 3 | Q3: R1013 | R3: 46 | T3: Total Customers Count | Z3: 2335
A4: Id3 | B4: Phil | C4: Lu | D4: 34.485 | E4: Obesity | F4: 11.87 | G4: Diabetes | H4: yes | I4: No | J4: No | K4: 2 | L4: =_xlfn.XLOOKUP(A4,'PWQ_Medical Examinations (2)'!A:A,'PWQ_Medical Examinations (2)'!I:I,"Not Found") -> yes | M4: 25822 | N4: 60021.4 | O4: tier - 1 | P4: tier - 1 | Q4: R1012 | R4: 52 | T4: Total Hospitalisation | Z4: 1579
A5: Id4 | B5: Kelsey | C5: Osborne | D5: 38.095 | E5: Obesity | F5: 6.05 | G5: Prediabetes | H5: No | I5: No | J5: No | K5: 0 | L5: =_xlfn.XLOOKUP(A5,'PWQ_Medical Examinations (2)'!A:A,'PWQ_Medical Examinations (2)'!I:I,"Not Found") -> yes | M5: 33395 | N5: 58571.07 | O5: tier - 1 | P5: tier - 3 | Q5: R1024 | R5: 32 | T5: Total Healthcare Cost | Z5: 31575276
A6: Id5 | B6: Kristyn | C6: Kadala | D6: 35.53 | E6: Obesity | F6: 5.45 | G6: Normal | H6: No | I6: No | J6: No | K6: 0 | L6: =_xlfn.XLOOKUP(A6,'PWQ_Medical Examinations (2)'!A:A,'PWQ_Medical Examinations (2)'!I:I,"Not Found") -> yes | M6: 32678 | N6: 55135.4 | O6: tier - 1 | P6: tier - 2 | Q6: R1012 | R6: 33 | T6: Average Cost and Medical Metrics | Z6: 13550
A7: Id6 | B7: Russell B | C7: Baker | D7: 32.8 | E7: Obesity | F7: 6.59 | G7: Diabetes | H7: No | I7: No | J7: No | K7: 0 | L7: =_xlfn.XLOOKUP(A7,'PWQ_Medical Examinations (2)'!A:A,'PWQ_Medical Examinations (2)'!I:I,"Not Found") -> yes | M7: 22862 | N7: 52590.83 | O7: tier - 1 | P7: tier - 3 | Q7: R1011 | R7: 60
A8: Id7 | B8: Scott | C8: Macpherson | D8: 36.4 | E8: Obesity | F8: 6.07 | G8: Prediabetes | H8: No | I8: No | J8: No | K8: 0 | L8: =_xlfn.XLOOKUP(A8,'PWQ_Medical Examinations (2)'!A:A,'PWQ_Medical Examinations (2)'!I:I,"Not Found") -> yes | M8: 34634 | N8: 51194.56 | O8: tier - 1 | P8: tier - 3 | Q8: R1011 | R8: 28
A9: Id8 | B9: Stephen | C9: Hallman | D9: 36.96 | E9: Obesity | F9: 7.93 | G9: Diabetes | H9: No | I9: No | J9: No | K9: 3 | L9: =_xlfn.XLOOKUP(A9,'PWQ_Medical Examinations (2)'!A:A,'PWQ_Medical Examinations (2)'!I:I,"Not Found") -> yes | M9: 21363 | N9: 49577.66 | O9: tier - 2 | P9: tier - 2 | Q9: R1013 | R9: 64
A10: Id9 | B10: Patrick R | C10: Moran | D10: 41.14 | E10: Obesity | F10: 9.58 | G10: Diabetes | H10: yes | I10: No | J10: Yes | K10: 1 | L10: =_xlfn.XLOOKUP(A10,'PWQ_Medical Examinations (2)'!A:A,'PWQ_Medical Examinations (2)'!I:I,"Not Found") -> yes | M10: 23258 | N10: 48970.25 | O10: tier - 1 | P10: tier - 2 | Q10: R1013 | R10: 59
A11: Id10 | B11: Brooke N | C11: Benner | D11: 38.06 | E11: Obesity | F11: 10.79 | G11: Diabetes | H11: No | I11: No | J11: No | K11: 0 | L11: =_xlfn.XLOOKUP(A11,'PWQ_Medical Examinations (2)'!A:A,'PWQ_Medical Examinations (2)'!I:I,"Not Found") -> yes | M11: 28853 | N11: 48885.14 | O11: tier - 1 | P11: tier - 2 | Q11: R1013 | R11: 44
A12: Id11 | B12: Paola Andrea | C12: Fierro Vargas | D12: 37.7 | E12: Obesity | F12: 5.96 | G12: Prediabetes | H12: yes | I12: No | J12: No | K12: 2 | L12: =_xlfn.XLOOKUP(A12,'PWQ_Medical Examinations (2)'!A:A,'PWQ_Medical Examinations (2)'!I:I,"Not Found") -> yes | M12: 21753 | N12: 48824.45 | O12: tier - 2 | P12: tier - 1 | Q12: R1011 | R12: 63
A13: Id12 | B13: David | C13: Franz | D13: 42.13 | E13: Obesity | F13: 11.9 | G13: Diabetes | H13: No | I13: No | J13: No | K13: 0 | L13: =_xlfn.XLOOKUP(A13,'PWQ_Medical Examinations (2)'!A:A,'PWQ_Medical Examinations (2)'!I:I,"Not Found") -> yes | M13: 24042 | N13: 48675.52 | O13: tier - 1 | P13: tier - 2 | Q13: R1013 | R13: 57
A14: Id13 | B14: Wade | C14: Foster | D14: 40.92 | E14: Obesity | F14: 8.41 | G14: Diabetes | H14: No | I14: No | J14: No | K14: 0 | L14: =_xlfn.XLOOKUP(A14,'PWQ_Medical Examinations (2)'!A:A,'PWQ_Medical Examinations (2)'!I:I,"Not Found") -> yes | M14: 22930 | N14: 48673.56 | O14: tier - 1 | P14: tier - 2 | Q14: R1013 | R14: 60
A15: Id14 | B15: Franklin | C15: Tenorio | D15: 40.565 | E15: Obesity | F15: 7.02 | G15: Diabetes | H15: No | I15: No | J15: No | K15: 0 | L15: =_xlfn.XLOOKUP(A15,'PWQ_Medical Examinations (2)'!A:A,'PWQ_Medical Examinations (2)'!I:I,"Not Found") -> yes | M15: 25173 | N15: 48549.18 | O15: tier - 1 | P15: tier - 3 | Q15: R1016 | R15: 54
A16: Id15 | B16: Leilani M | C16: Rios | D16: 36.385 | E16: Obesity | F16: 7.59 | G16: Diabetes | H16: yes | I16: No | J16: No | K16: 2 | L16: =_xlfn.XLOOKUP(A16,'PWQ_Medical Examinations (2)'!A:A,'PWQ_Medical Examinations (2)'!I:I,"Not Found") -> yes | M16: 22636 | N16: 48517.56 | O16: tier - 1 | P16: tier - 3 | Q16: R1024 | R16: 61
A17: Id16 | B17: Philippe | C17: Viau-Dupuis | D17: 39.9 | E17: Obesity | F17: 11.32 | G17: Diabetes | H17: No | I17: No | J17: No | K17: 0 | L17: =_xlfn.XLOOKUP(A17,'PWQ_Medical Examinations (2)'!A:A,'PWQ_Medical Examinations (2)'!I:I,"Not Found") -> yes | M17: 22885 | N17: 48173.36 | O17: tier - 1 | P17: tier - 3 | Q17: R1011 | R17: 60
A18: Id17 | B18: Jennifer A | C18: Cronin | D18: 33.8 | E18: Obesity | F18: 7.67 | G18: Diabetes | H18: No | I18: No | J18: No | K18: 3 | L18: =_xlfn.XLOOKUP(A18,'PWQ_Medical Examinations (2)'!A:A,'PWQ_Medical Examinations (2)'!I:I,"Not Found") -> yes | M18: 21505 | N18: 47928.03 | O18: tier - 2 | P18: tier - 3 | Q18: R1011 | R18: 64
... A1286: Id1285 | B1286: Rebecca E | C1286: Bokun | D1286: 32 | E1286: Obesity | F1286: 7.85 | G1286: Diabetes | H1286: yes | I1286: No | J1286: No | K1286: 1 | L1286: =_xlfn.XLOOKUP(A1286,'PWQ_Medical Examinations (2)'!A:A,'PWQ_Medical Examinations (2)'!I:I,"Not Found") -> No | M1286: 27612 | N1286: 8551.35 | O1286: tier - 2 | P1286: tier - 2 | Q1286: R1011 | R1286: 47
A1287: Id1286 | B1287: Katie M | C1287: Ainsley | D1287: 29.37 | E1287: Over weight | F1287: 8.01 | G1287: Diabetes | H1287: yes | I1287: No | J1287: No | K1287: 1 | L1287: =_xlfn.XLOOKUP(A1287,'PWQ_Medical Examinations (2)'!A:A,'PWQ_Medical Examinations (2)'!I:I,"Not Found") -> No | M1287: 34264 | N1287: 400 | O1287: tier-2 | P1287: Not Found | Q1287: Unknown | R1287: Not Found
A1288: Id1287 | B1288: Elizabeth A | C1288: Foster | D1288: 23.6 | E1288: Normal Weight | F1288: 7.4 | G1288: Diabetes | H1288: yes | I1288: No | J1288: No | K1288: 1 | L1288: =_xlfn.XLOOKUP(A1288,'PWQ_Medical Examinations (2)'!A:A,'PWQ_Medical Examinations (2)'!I:I,"Not Found") -> No | M1288: 27704 | N1288: 8539.67 | O1288: tier - 2 | P1288: tier - 3 | Q1288: R1011 | R1288: 47
A1289: Id1288 | B1289: Sarah | C1289: Overpeck | D1289: 33.155 | E1289: Obesity | F1289: 8.38 | G1289: Diabetes | H1289: yes | I1289: No | J1289: No | K1289: 0 | L1289: =_xlfn.XLOOKUP(A1289,'PWQ_Medical Examinations (2)'!A:A,'PWQ_Medical Examinations (2)'!I:I,"Not Found") -> No | M1289: 29947 | N1289: 8538.29 | O1289: tier - 2 | P1289: tier - 3 | Q1289: R1024 | R1289: 41
A1290: Id1289 | B1290: Annie J | C1290: Levine | D1290: 24.32 | E1290: Normal Weight | F1290: 11.56 | G1290: Diabetes | H1290: yes | I1290: No | J1290: No | K1290: 1 | L1290: =_xlfn.XLOOKUP(A1290,'PWQ_Medical Examinations (2)'!A:A,'PWQ_Medical Examinations (2)'!I:I,"Not Found") -> No | M1290: 29474 | N1290: 300 | O1290: tier-2 | P1290: Not Found | Q1290: Unknown | R1290: Not Found
A1291: Id1290 | B1291: Annie | C1291: Jean | D1291: 36.3 | E1291: Obesity | F1291: 4.61 | G1291: Normal | H1291: No | I1291: No | J1291: No | K1291: 0 | L1291: =_xlfn.XLOOKUP(A1291,'PWQ_Medical Examinations (2)'!A:A,'PWQ_Medical Examinations (2)'!I:I,"Not Found") -> No | M1291: 28332 | N1291: 8527.53 | O1291: tier - 2 | P1291: tier - 2 | Q1291: R1013 | R1291: 45
A1292: Id1291 | B1292: Lindsey | C1292: Wild | D1292: 34.4 | E1292: Obesity | F1292: 4.95 | G1292: Normal | H1292: No | I1292: No | J1292: Yes | K1292: 1 | L1292: =_xlfn.XLOOKUP(A1292,'PWQ_Medical Examinations (2)'!A:A,'PWQ_Medical Examinations (2)'!I:I,"Not Found") -> No | M1292: 29080 | N1292: 8522 | O1292: tier - 2 | P1292: tier - 2 | Q1292: R1011 | R1292: 43
A1293: Id1292 | B1293: Laura | C1293: Tabor | D1293: 30.9 | E1293: Obesity | F1293: 5.04 | G1293: Normal | H1293: No | I1293: No | J1293: No | K1293: 0 | L1293: =_xlfn.XLOOKUP(A1293,'PWQ_Medical Examinations (2)'!A:A,'PWQ_Medical Examinations (2)'!I:I,"Not Found") -> No | M1293: 28488 | N1293: 8520.03 | O1293: tier - 2 | P1293: tier - 3 | Q1293: R1011 | R1293: 45
A1294: Id1293 | B1294: Amy T | C1294: Steffen | D1294: 28.6 | E1294: Over weight | F1294: 5.42 | G1294: Normal | H1294: No | I1294: No | J1294: No | K1294: 0 | L1294: =_xlfn.XLOOKUP(A1294,'PWQ_Medical Examinations (2)'!A:A,'PWQ_Medical Examinations (2)'!I:I,"Not Found") -> No | M1294: 28297 | N1294: 8516.83 | O1294: tier - 2 | P1294: tier - 1 | Q1294: R1013 | R1294: 45
A1295: Id1294 | B1295: Katarina D | C1295: Tadich | D1295: 27.83 | E1295: Over weight | F1295: 5.39 | G1295: Normal | H1295: No | I1295: No | J1295: No | K1295: 0 | L1295: =_xlfn.XLOOKUP(A1295,'PWQ_Medical Examinations (2)'!A:A,'PWQ_Medical Examinations (2)'!I:I,"Not Found") -> No | M1295: 28485 | N1295: 8515.76 | O1295: tier - 2 | P1295: tier - 2 | Q1295: R1013 | R1295: 45
A1296: Id1295 | B1296: Bj | C1296: Christenson | D1296: 39.64 | E1296: Obesity | F1296: 6 | G1296: Prediabetes | H1296: No | I1296: No | J1296: Yes | K1296: 1 | L1296: =_xlfn.XLOOKUP(A1296,'PWQ_Medical Examinations (2)'!A:A,'PWQ_Medical Examinations (2)'!I:I,"Not Found") -> No | M1296: 34283 | N1296: 8471.65 | O1296: tier - 2 | P1296: tier - 1 | Q1296: R1012 | R1296: 29
A1297: Id1296 | B1297: Alison | C1297: Shell | D1297: 38.48 | E1297: Obesity | F1297: 6.02 | G1297: Prediabetes | H1297: No | I1297: No | J1297: No | K1297: 1 | L1297: =_xlfn.XLOOKUP(A1297,'PWQ_Medical Examinations (2)'!A:A,'PWQ_Medical Examinations (2)'!I:I,"Not Found") -> No | M1297: 33856 | N1297: 8466.35 | O1297: tier - 2 | P1297: tier - 2 | Q1297: R1012 | R1297: 30
A1298: Id1297 | B1298: Neil K | C1298: Rao | D1298: 36.2 | E1298: Obesity | F1298: 4.62 | G1298: Normal | H1298: No | I1298: No | J1298: No | K1298: 2 | L1298: =_xlfn.XLOOKUP(A1298,'PWQ_Medical Examinations (2)'!A:A,'PWQ_Medical Examinations (2)'!I:I,"Not Found") -> No | M1298: 26659 | N1298: 8457.82 | O1298: tier - 2 | P1298: tier - 3 | Q1298: R1011 | R1298: 50
A1299: Id1298 | B1299: s Anne Hunter | C1299: Myers | D1299: 27.13 | E1299: Over weight | F1299: 5.59 | G1299: Normal | H1299: No | I1299: No | J1299: No | K1299: 1 | L1299: =_xlfn.XLOOKUP(A1299,'PWQ_Medical Examinations (2)'!A:A,'PWQ_Medical Examinations (2)'!I:I,"Not Found") -> No | M1299: 30852 | N1299: 8450.82 | O1299: tier - 2 | P1299: tier - 2 | Q1299: R1025 | R1299: 38
A1300: Id1299 | B1300: Sandra | C1300: McLean | D1300: 20.75 | E1300: Normal Weight | F1300: 5.18 | G1300: Normal | H1300: yes | I1300: No | J1300: No | K1300: 2 | L1300: =_xlfn.XLOOKUP(A1300,'PWQ_Medical Examinations (2)'!A:A,'PWQ_Medical Examinations (2)'!I:I,"Not Found") -> No | M1300: 24270 | N1300: 8448.66 | O1300: tier - 3 | P1300: tier - 1 | Q1300: R1013 | R1300: 56
A1301: Id1300 | B1301: Robert | C1301: Gomez | D1301: 26.6 | E1301: Over weight | F1301: 6.29 | G1301: Prediabetes | H1301: No | I1301: No | J1301: No | K1301: 2 | L1301: =_xlfn.XLOOKUP(A1301,'PWQ_Medical Examinations (2)'!A:A,'PWQ_Medical Examinations (2)'!I:I,"Not Found") -> No | M1301: 26546 | N1301: 8444.47 | O1301: tier - 3 | P1301: tier - 1 | Q1301: R1011 | R1301: 50
A1302: Id1301 | B1302: Rodney | C1302: Hemingway | D1302: 25.3 | E1302: Over weight | F1302: 4.49 | G1302: Normal | H1302: No | I1302: No | J1302: No | K1302: 2 | L1302: =_xlfn.XLOOKUP(A1302,'PWQ_Medical Examinations (2)'!A:A,'PWQ_Medical Examinations (2)'!I:I,"Not Found") -> No | M1302: 26551 | N1302: 8442.67 | O1302: tier - 2 | P1302: tier - 3 | Q1302: R1013 | R1302: 50
... A2336: Id2335 | B2336: Aaron K | C2336: German | D2336: 17.58 | E2336: Under Weight | F2336: 4.51 | G2336: Normal | H2336: No | I2336: No | J2336: No | K2336: 1 | L2336: =_xlfn.XLOOKUP(A2336,'PWQ_Medical Examinations (2)'!A:A,'PWQ_Medical Examinations (2)'!I:I,"Not Found") -> No | M2336: 33794 | N2336: 563.84 | O2336: tier - 2 | P2336: tier - 3 | Q2336: R1013 | R2336: 30
K2337: =SUM(K2:K2336) -> 1579
B2339: =COUNTA(B2:B2336) -> 2335 | D2339: =SUM(D2:D2336) -> 72321.135 | E2339: =SUM(E2:E2336) -> 0 | F2339: =SUM(F2:F2336) -> 15361.96 | G2339: =SUM(G2:G2336) -> 0 | H2339: =SUM(H2:H2336) -> 0 | I2339: =SUM(I2:I2336) -> 0 | J2339: =SUM(J2:J2336) -> 0 | L2339: =SUM(L2:L2336) -> 0 | M2339: =SUM(M2:M2336) -> 71226005 | N2339: =SUM(N2:N2336) -> 31575976 | O2339: =SUM(O2:O2336) -> 0 | P2339: =SUM(P2:P2336) -> 0 | Q2339: =SUM(Q2:Q2336) -> 0 | R2339: =SUM(R2:R2336) -> 91521

Sheet Hospitalisation Details
A1: Customer ID | B1: year | C1: month | D1: date | E1: children | F1: charges | G1: Hospital tier | H1: City tier | I1: State ID
A2: Id2335 | B2: 1992 | C2: Jul | D2: 19 | E2: 0 | F2: 563.84 | G2: tier - 2 | H2: tier - 3 | I2: R1013
A3: Id2334 | B3: 1992 | C3: Nov | D3: 30 | E3: 0 | F3: 570.62 | G3: tier - 2 | H3: tier - 1 | I3: R1013
A4: Id2333 | B4: 1993 | C4: Jun | D4: 30 | E4: 0 | F4: 600 | G4: tier - 2 | H4: tier - 1 | I4: R1013
A5: Id2332 | B5: 1992 | C5: Sep | D5: 13 | E5: 0 | F5: 604.54 | G5: tier - 3 | H5: tier - 3 | I5: R1013
A6: Id2331 | B6: 1998 | C6: Jul | D6: 27 | E6: 0 | F6: 637.26 | G6: tier - 3 | H6: tier - 3 | I6: R1013
A7: Id2330 | B7: 2001 | C7: Nov | D7: 20 | E7: 0 | F7: 646.14 | G7: tier - 3 | H7: tier - 3 | I7: R1012
A8: Id2329 | B8: 1993 | C8: Jun | D8: 1 | E8: 0 | F8: 650 | G8: tier - 3 | H8: tier - 3 | I8: R1013
A9: Id2328 | B9: 1995 | C9: Jul | D9: 4 | E9: 0 | F9: 650 | G9: tier - 3 | H9: tier - 3 | I9: R1013
A10: Id2327 | B10: 2002 | C10: Nov | D10: 29 | E10: 0 | F10: 668 | G10: tier - 3 | H10: tier - 2 | I10: R1012
A11: Id2326 | B11: 1997 | C11: Nov | D11: 9 | E11: 0 | F11: 670 | G11: tier - 3 | H11: tier - 3 | I11: R1013
A12: Id2325 | B12: 2001 | C12: Sep | D12: 12 | E12: 0 | F12: 687.54 | G12: tier - 3 | H12: tier - 2 | I12: R1013
A13: Id2324 | B13: 1999 | C13: Dec | D13: 26 | E13: 0 | F13: 700 | G13: ? | H13: tier - 3 | I13: R1013
... A1050: Id1290 | B1050: 1977 | C1050: Jul | D1050: 26 | E1050: 2 | F1050: 8527.53 | G1050: tier - 2 | H1050: tier - 2 | I1050: R1013
A1051: Id1289 | B1051: ? | C1051: Jul | D1051: 24 | E1051: 0 | F1051: 8534.67 | G1051: tier - 2 | H1051: tier - 3 | I1051: R1024
A1052: Id1288 | B1052: 1981 | C1052: Dec | D1052: 27 | E1052: 3 | F1052: 8538.29 | G1052: tier - 2 | H1052: tier - 3 | I1052: R1024
A1053: Id1287 | B1053: 1975 | C1053: Nov | D1053: 6 | E1053: 1 | F1053: 8539.67 | G1053: tier - 2 | H1053: tier - 3 | I1053: R1011
A1054: Id1286 | B1054: ? | C1054: Dec | D1054: 12 | E1054: 1 | F1054: 8547.69 | G1054: tier - 2 | H1054: tier - 1 | I1054: R1013
A1055: Id1285 | B1055: 1975 | C1055: Aug | D1055: 6 | E1055: 1 | F1055: 8551.35 | G1055: tier - 2 | H1055: tier - 2 | I1055: R1011
A1056: Id1284 | B1056: 1975 | C1056: Aug | D1056: 21 | E1056: 1 | F1056: 8556.91 | G1056: tier - 2 | H1056: tier - 1 | I1056: R1011
A1057: Id1283 | B1057: 1988 | C1057: Sep | D1057: 21 | E1057: 3 | F1057: 8567.25 | G1057: tier - 2 | H1057: tier - 1 | I1057: R1012
A1058: Id1282 | B1058: 1975 | C1058: Sep | D1058: 26 | E1058: 1 | F1058: 8569.86 | G1058: tier - 2 | H1058: tier - 3 | I1058: R1013
A1059: Id1281 | B1059: 1982 | C1059: Dec | D1059: 6 | E1059: 3 | F1059: 8572.04 | G1059: tier - 2 | H1059: tier - 2 | I1059: R1021
A1060: Id1280 | B1060: 1987 | C1060: Nov | D1060: 11 | E1060: 3 | F1060: 8573.3 | G1060: tier - 2 | H1060: tier - 2 | I1060: R1021
A1061: Id1279 | B1061: 1983 | C1061: Dec | D1061: 30 | E1061: 5 | F1061: 8582.3 | G1061: tier - 2 | H1061: tier - 1 | I1061: R1013
A1062: Id1278 | B1062: 1983 | C1062: Jul | D1062: 25 | E1062: 5 | F1062: 8596.83 | G1062: tier - 2 | H1062: tier - 3 | I1062: R1013
A1063: Id1277 | B1063: 1973 | C1063: Jul | D1063: 11 | E1063: 0 | F1063: 8601.33 | G1063: tier - 2 | H1063: tier - 1 | I1063: R1013
A1064: Id1276 | B1064: 1977 | C1064: Sep | D1064: 24 | E1064: 2 | F1064: 8603.82 | G1064: tier - 2 | H1064: tier - 1 | I1064: R1019
A1065: Id1275 | B1065: 1977 | C1065: Nov | D1065: 12 | E1065: 2 | F1065: 8604.48 | G1065: tier - 3 | H1065: tier - 2 | I1065: R1016
A1066: Id1274 | B1066: 1977 | C1066: Oct | D1066: 15 | E1066: 3 | F1066: 8605.36 | G1066: tier - 2 | H1066: tier - 2 | I1066: R1013
... A2344: Id1 | B2344: 1968 | C2344: Oct | D2344: 12 | E2344: 0 | F2344: 63770.43 | G2344: tier - 1 | H2344: tier - 3 | I2344: R1013

Sheet Dashboard
G2: Healthcare Dashboard – AI Analysis
N21: sss
